<?xml version="1.0"?>

<robot xmlns="http://drake.mit.edu"
       xmlns:xsi="http://www.w3.org/2001/XMLSchema-instance"
       name="Pivot">

    <link name="world">
    </link>

    <joint name="pivot" type="revolute">
        <parent link="world"/>
        <child link="pivot_link"/>
        <axis xyz="0 1 0"/>
        <limit lower="-6.28" upper="6.28"/>
        <dynamics damping="0.0" friction="0.0"/>
    </joint>

    <link name="pivot_link">
        <inertial>
            <origin xyz="0.025 0 0.025"/>
            <mass value="1.0"/>
            <inertia ixx="1.0" iyy="1.0" izz="1.0" ixy="0.0" ixz="0.0" iyz="0.0"/>
        </inertial>
        <visual>
            <origin xyz="0.025 0 0.025"/>
            <geometry>
                <box size="0.05 0.05 0.05"/>
            </geometry>
            <material>
                <color rgba="0.5 0.5 0.5 0.5"/>
            </material>
        </visual>
        <collision>
            <origin xyz="0.025 0 0.025"/>
            <geometry>
                <box size="0.05 0.05 0.05"/>
            </geometry>
            <drake:proximity_properties>
                <drake:compliant_hydroelastic/>
                <drake:mesh_resolution_hint value="0.1"/>
                <drake:hydroelastic_modulus value="5e7"/>
                <drake:hunt_crossley_dissipation value="200.0"/>
                <drake:mu_dynamic value="1.0"/>
                <drake:mu_static value="1.0"/>
            </drake:proximity_properties>
        </collision>
    </link>
</robot>